beginning eval alpaca_data_1000
2025-03-30 23:10:54.130197: I tensorflow/core/util/port.cc:153] oneDNN custom operations are on. You may see slightly different numerical results due to floating-point round-off errors from different computation orders. To turn them off, set the environment variable `TF_ENABLE_ONEDNN_OPTS=0`.
2025-03-30 23:10:54.314088: E external/local_xla/xla/stream_executor/cuda/cuda_fft.cc:467] Unable to register cuFFT factory: Attempting to register factory for plugin cuFFT when one has already been registered
WARNING: All log messages before absl::InitializeLog() is called are written to STDERR
E0000 00:00:1743390654.372377 3477609 cuda_dnn.cc:8579] Unable to register cuDNN factory: Attempting to register factory for plugin cuDNN when one has already been registered
E0000 00:00:1743390654.395959 3477609 cuda_blas.cc:1407] Unable to register cuBLAS factory: Attempting to register factory for plugin cuBLAS when one has already been registered
W0000 00:00:1743390654.497373 3477609 computation_placer.cc:177] computation placer already registered. Please check linkage and avoid linking the same target more than once.
W0000 00:00:1743390654.497732 3477609 computation_placer.cc:177] computation placer already registered. Please check linkage and avoid linking the same target more than once.
W0000 00:00:1743390654.497734 3477609 computation_placer.cc:177] computation placer already registered. Please check linkage and avoid linking the same target more than once.
W0000 00:00:1743390654.497736 3477609 computation_placer.cc:177] computation placer already registered. Please check linkage and avoid linking the same target more than once.
2025-03-30 23:10:54.506035: I tensorflow/core/platform/cpu_feature_guard.cc:210] This TensorFlow binary is optimized to use available CPU instructions in performance-critical operations.
To enable the following instructions: AVX2 AVX512F AVX512_VNNI FMA, in other operations, rebuild TensorFlow with the appropriate compiler flags.
Loading model: Llama-3.2-3B-Instruct
Traceback (most recent call last):
  File "/home/janeec/.conda/envs/FairTune/lib/python3.10/site-packages/urllib3/connection.py", line 196, in _new_conn
    sock = connection.create_connection(
  File "/home/janeec/.conda/envs/FairTune/lib/python3.10/site-packages/urllib3/util/connection.py", line 60, in create_connection
    for res in socket.getaddrinfo(host, port, family, socket.SOCK_STREAM):
  File "/home/janeec/.conda/envs/FairTune/lib/python3.10/socket.py", line 967, in getaddrinfo
    for res in _socket.getaddrinfo(host, port, family, type, proto, flags):
socket.gaierror: [Errno -2] Name or service not known

The above exception was the direct cause of the following exception:

Traceback (most recent call last):
  File "/home/janeec/.conda/envs/FairTune/lib/python3.10/site-packages/urllib3/connectionpool.py", line 789, in urlopen
    response = self._make_request(
  File "/home/janeec/.conda/envs/FairTune/lib/python3.10/site-packages/urllib3/connectionpool.py", line 490, in _make_request
    raise new_e
  File "/home/janeec/.conda/envs/FairTune/lib/python3.10/site-packages/urllib3/connectionpool.py", line 466, in _make_request
    self._validate_conn(conn)
  File "/home/janeec/.conda/envs/FairTune/lib/python3.10/site-packages/urllib3/connectionpool.py", line 1095, in _validate_conn
    conn.connect()
  File "/home/janeec/.conda/envs/FairTune/lib/python3.10/site-packages/urllib3/connection.py", line 615, in connect
    self.sock = sock = self._new_conn()
  File "/home/janeec/.conda/envs/FairTune/lib/python3.10/site-packages/urllib3/connection.py", line 203, in _new_conn
    raise NameResolutionError(self.host, self, e) from e
urllib3.exceptions.NameResolutionError: <urllib3.connection.HTTPSConnection object at 0x14b6ecaf08b0>: Failed to resolve 'huggingface.co' ([Errno -2] Name or service not known)

The above exception was the direct cause of the following exception:

Traceback (most recent call last):
  File "/home/janeec/.conda/envs/FairTune/lib/python3.10/site-packages/requests/adapters.py", line 667, in send
    resp = conn.urlopen(
  File "/home/janeec/.conda/envs/FairTune/lib/python3.10/site-packages/urllib3/connectionpool.py", line 843, in urlopen
    retries = retries.increment(
  File "/home/janeec/.conda/envs/FairTune/lib/python3.10/site-packages/urllib3/util/retry.py", line 519, in increment
    raise MaxRetryError(_pool, url, reason) from reason  # type: ignore[arg-type]
urllib3.exceptions.MaxRetryError: HTTPSConnectionPool(host='huggingface.co', port=443): Max retries exceeded with url: /Llama-3.2-3B-Instruct/resolve/main/config.json (Caused by NameResolutionError("<urllib3.connection.HTTPSConnection object at 0x14b6ecaf08b0>: Failed to resolve 'huggingface.co' ([Errno -2] Name or service not known)"))

During handling of the above exception, another exception occurred:

Traceback (most recent call last):
  File "/home/janeec/.conda/envs/FairTune/lib/python3.10/site-packages/huggingface_hub/file_download.py", line 1376, in _get_metadata_or_catch_error
    metadata = get_hf_file_metadata(
  File "/home/janeec/.conda/envs/FairTune/lib/python3.10/site-packages/huggingface_hub/utils/_validators.py", line 114, in _inner_fn
    return fn(*args, **kwargs)
  File "/home/janeec/.conda/envs/FairTune/lib/python3.10/site-packages/huggingface_hub/file_download.py", line 1296, in get_hf_file_metadata
    r = _request_wrapper(
  File "/home/janeec/.conda/envs/FairTune/lib/python3.10/site-packages/huggingface_hub/file_download.py", line 280, in _request_wrapper
    response = _request_wrapper(
  File "/home/janeec/.conda/envs/FairTune/lib/python3.10/site-packages/huggingface_hub/file_download.py", line 303, in _request_wrapper
    response = get_session().request(method=method, url=url, **params)
  File "/home/janeec/.conda/envs/FairTune/lib/python3.10/site-packages/requests/sessions.py", line 589, in request
    resp = self.send(prep, **send_kwargs)
  File "/home/janeec/.conda/envs/FairTune/lib/python3.10/site-packages/requests/sessions.py", line 703, in send
    r = adapter.send(request, **kwargs)
  File "/home/janeec/.conda/envs/FairTune/lib/python3.10/site-packages/huggingface_hub/utils/_http.py", line 96, in send
    return super().send(request, *args, **kwargs)
  File "/home/janeec/.conda/envs/FairTune/lib/python3.10/site-packages/requests/adapters.py", line 700, in send
    raise ConnectionError(e, request=request)
requests.exceptions.ConnectionError: (MaxRetryError('HTTPSConnectionPool(host=\'huggingface.co\', port=443): Max retries exceeded with url: /Llama-3.2-3B-Instruct/resolve/main/config.json (Caused by NameResolutionError("<urllib3.connection.HTTPSConnection object at 0x14b6ecaf08b0>: Failed to resolve \'huggingface.co\' ([Errno -2] Name or service not known)"))'), '(Request ID: 553a8016-1078-451c-b231-973b660350d6)')

The above exception was the direct cause of the following exception:

Traceback (most recent call last):
  File "/home/janeec/.conda/envs/FairTune/lib/python3.10/site-packages/transformers/utils/hub.py", line 424, in cached_files
    hf_hub_download(
  File "/home/janeec/.conda/envs/FairTune/lib/python3.10/site-packages/huggingface_hub/utils/_validators.py", line 114, in _inner_fn
    return fn(*args, **kwargs)
  File "/home/janeec/.conda/envs/FairTune/lib/python3.10/site-packages/huggingface_hub/file_download.py", line 862, in hf_hub_download
    return _hf_hub_download_to_cache_dir(
  File "/home/janeec/.conda/envs/FairTune/lib/python3.10/site-packages/huggingface_hub/file_download.py", line 969, in _hf_hub_download_to_cache_dir
    _raise_on_head_call_error(head_call_error, force_download, local_files_only)
  File "/home/janeec/.conda/envs/FairTune/lib/python3.10/site-packages/huggingface_hub/file_download.py", line 1489, in _raise_on_head_call_error
    raise LocalEntryNotFoundError(
huggingface_hub.errors.LocalEntryNotFoundError: An error happened while trying to locate the file on the Hub and we cannot find the requested files in the local cache. Please check your connection and try again or make sure your Internet connection is on.

The above exception was the direct cause of the following exception:

Traceback (most recent call last):
  File "/home/janeec/FairTune/get_salinas_results/eval_salinas.py", line 107, in <module>
    main()
  File "/home/janeec/FairTune/get_salinas_results/eval_salinas.py", line 86, in main
    tokenizer = AutoTokenizer.from_pretrained(BASE_MODEL)
  File "/home/janeec/.conda/envs/FairTune/lib/python3.10/site-packages/transformers/models/auto/tokenization_auto.py", line 930, in from_pretrained
    config = AutoConfig.from_pretrained(
  File "/home/janeec/.conda/envs/FairTune/lib/python3.10/site-packages/transformers/models/auto/configuration_auto.py", line 1096, in from_pretrained
    config_dict, unused_kwargs = PretrainedConfig.get_config_dict(pretrained_model_name_or_path, **kwargs)
  File "/home/janeec/.conda/envs/FairTune/lib/python3.10/site-packages/transformers/configuration_utils.py", line 594, in get_config_dict
    config_dict, kwargs = cls._get_config_dict(pretrained_model_name_or_path, **kwargs)
  File "/home/janeec/.conda/envs/FairTune/lib/python3.10/site-packages/transformers/configuration_utils.py", line 653, in _get_config_dict
    resolved_config_file = cached_file(
  File "/home/janeec/.conda/envs/FairTune/lib/python3.10/site-packages/transformers/utils/hub.py", line 266, in cached_file
    file = cached_files(path_or_repo_id=path_or_repo_id, filenames=[filename], **kwargs)
  File "/home/janeec/.conda/envs/FairTune/lib/python3.10/site-packages/transformers/utils/hub.py", line 491, in cached_files
    raise EnvironmentError(
OSError: We couldn't connect to 'https://huggingface.co' to load the files, and couldn't find them in the cached files.
Checkout your internet connection or see how to run the library in offline mode at 'https://huggingface.co/docs/transformers/installation#offline-mode'.
end eval alpaca_data_1000
beginning eval educational_1000
2025-03-30 23:11:09.391295: I tensorflow/core/util/port.cc:153] oneDNN custom operations are on. You may see slightly different numerical results due to floating-point round-off errors from different computation orders. To turn them off, set the environment variable `TF_ENABLE_ONEDNN_OPTS=0`.
2025-03-30 23:11:09.404632: E external/local_xla/xla/stream_executor/cuda/cuda_fft.cc:467] Unable to register cuFFT factory: Attempting to register factory for plugin cuFFT when one has already been registered
WARNING: All log messages before absl::InitializeLog() is called are written to STDERR
E0000 00:00:1743390669.419309 3478680 cuda_dnn.cc:8579] Unable to register cuDNN factory: Attempting to register factory for plugin cuDNN when one has already been registered
E0000 00:00:1743390669.423802 3478680 cuda_blas.cc:1407] Unable to register cuBLAS factory: Attempting to register factory for plugin cuBLAS when one has already been registered
W0000 00:00:1743390669.436273 3478680 computation_placer.cc:177] computation placer already registered. Please check linkage and avoid linking the same target more than once.
W0000 00:00:1743390669.436292 3478680 computation_placer.cc:177] computation placer already registered. Please check linkage and avoid linking the same target more than once.
W0000 00:00:1743390669.436294 3478680 computation_placer.cc:177] computation placer already registered. Please check linkage and avoid linking the same target more than once.
W0000 00:00:1743390669.436296 3478680 computation_placer.cc:177] computation placer already registered. Please check linkage and avoid linking the same target more than once.
2025-03-30 23:11:09.440231: I tensorflow/core/platform/cpu_feature_guard.cc:210] This TensorFlow binary is optimized to use available CPU instructions in performance-critical operations.
To enable the following instructions: AVX2 AVX512F AVX512_VNNI FMA, in other operations, rebuild TensorFlow with the appropriate compiler flags.
Loading model: Llama-3.2-3B-Instruct
Traceback (most recent call last):
  File "/home/janeec/.conda/envs/FairTune/lib/python3.10/site-packages/urllib3/connection.py", line 196, in _new_conn
    sock = connection.create_connection(
  File "/home/janeec/.conda/envs/FairTune/lib/python3.10/site-packages/urllib3/util/connection.py", line 60, in create_connection
    for res in socket.getaddrinfo(host, port, family, socket.SOCK_STREAM):
  File "/home/janeec/.conda/envs/FairTune/lib/python3.10/socket.py", line 967, in getaddrinfo
    for res in _socket.getaddrinfo(host, port, family, type, proto, flags):
socket.gaierror: [Errno -2] Name or service not known

The above exception was the direct cause of the following exception:

Traceback (most recent call last):
  File "/home/janeec/.conda/envs/FairTune/lib/python3.10/site-packages/urllib3/connectionpool.py", line 789, in urlopen
    response = self._make_request(
  File "/home/janeec/.conda/envs/FairTune/lib/python3.10/site-packages/urllib3/connectionpool.py", line 490, in _make_request
    raise new_e
  File "/home/janeec/.conda/envs/FairTune/lib/python3.10/site-packages/urllib3/connectionpool.py", line 466, in _make_request
    self._validate_conn(conn)
  File "/home/janeec/.conda/envs/FairTune/lib/python3.10/site-packages/urllib3/connectionpool.py", line 1095, in _validate_conn
    conn.connect()
  File "/home/janeec/.conda/envs/FairTune/lib/python3.10/site-packages/urllib3/connection.py", line 615, in connect
    self.sock = sock = self._new_conn()
  File "/home/janeec/.conda/envs/FairTune/lib/python3.10/site-packages/urllib3/connection.py", line 203, in _new_conn
    raise NameResolutionError(self.host, self, e) from e
urllib3.exceptions.NameResolutionError: <urllib3.connection.HTTPSConnection object at 0x14eea8c5c8b0>: Failed to resolve 'huggingface.co' ([Errno -2] Name or service not known)

The above exception was the direct cause of the following exception:

Traceback (most recent call last):
  File "/home/janeec/.conda/envs/FairTune/lib/python3.10/site-packages/requests/adapters.py", line 667, in send
    resp = conn.urlopen(
  File "/home/janeec/.conda/envs/FairTune/lib/python3.10/site-packages/urllib3/connectionpool.py", line 843, in urlopen
    retries = retries.increment(
  File "/home/janeec/.conda/envs/FairTune/lib/python3.10/site-packages/urllib3/util/retry.py", line 519, in increment
    raise MaxRetryError(_pool, url, reason) from reason  # type: ignore[arg-type]
urllib3.exceptions.MaxRetryError: HTTPSConnectionPool(host='huggingface.co', port=443): Max retries exceeded with url: /Llama-3.2-3B-Instruct/resolve/main/config.json (Caused by NameResolutionError("<urllib3.connection.HTTPSConnection object at 0x14eea8c5c8b0>: Failed to resolve 'huggingface.co' ([Errno -2] Name or service not known)"))

During handling of the above exception, another exception occurred:

Traceback (most recent call last):
  File "/home/janeec/.conda/envs/FairTune/lib/python3.10/site-packages/huggingface_hub/file_download.py", line 1376, in _get_metadata_or_catch_error
    metadata = get_hf_file_metadata(
  File "/home/janeec/.conda/envs/FairTune/lib/python3.10/site-packages/huggingface_hub/utils/_validators.py", line 114, in _inner_fn
    return fn(*args, **kwargs)
  File "/home/janeec/.conda/envs/FairTune/lib/python3.10/site-packages/huggingface_hub/file_download.py", line 1296, in get_hf_file_metadata
    r = _request_wrapper(
  File "/home/janeec/.conda/envs/FairTune/lib/python3.10/site-packages/huggingface_hub/file_download.py", line 280, in _request_wrapper
    response = _request_wrapper(
  File "/home/janeec/.conda/envs/FairTune/lib/python3.10/site-packages/huggingface_hub/file_download.py", line 303, in _request_wrapper
    response = get_session().request(method=method, url=url, **params)
  File "/home/janeec/.conda/envs/FairTune/lib/python3.10/site-packages/requests/sessions.py", line 589, in request
    resp = self.send(prep, **send_kwargs)
  File "/home/janeec/.conda/envs/FairTune/lib/python3.10/site-packages/requests/sessions.py", line 703, in send
    r = adapter.send(request, **kwargs)
  File "/home/janeec/.conda/envs/FairTune/lib/python3.10/site-packages/huggingface_hub/utils/_http.py", line 96, in send
    return super().send(request, *args, **kwargs)
  File "/home/janeec/.conda/envs/FairTune/lib/python3.10/site-packages/requests/adapters.py", line 700, in send
    raise ConnectionError(e, request=request)
requests.exceptions.ConnectionError: (MaxRetryError('HTTPSConnectionPool(host=\'huggingface.co\', port=443): Max retries exceeded with url: /Llama-3.2-3B-Instruct/resolve/main/config.json (Caused by NameResolutionError("<urllib3.connection.HTTPSConnection object at 0x14eea8c5c8b0>: Failed to resolve \'huggingface.co\' ([Errno -2] Name or service not known)"))'), '(Request ID: 6a94fbbd-e84a-4e9a-91e4-ccffc7793c9d)')

The above exception was the direct cause of the following exception:

Traceback (most recent call last):
  File "/home/janeec/.conda/envs/FairTune/lib/python3.10/site-packages/transformers/utils/hub.py", line 424, in cached_files
    hf_hub_download(
  File "/home/janeec/.conda/envs/FairTune/lib/python3.10/site-packages/huggingface_hub/utils/_validators.py", line 114, in _inner_fn
    return fn(*args, **kwargs)
  File "/home/janeec/.conda/envs/FairTune/lib/python3.10/site-packages/huggingface_hub/file_download.py", line 862, in hf_hub_download
    return _hf_hub_download_to_cache_dir(
  File "/home/janeec/.conda/envs/FairTune/lib/python3.10/site-packages/huggingface_hub/file_download.py", line 969, in _hf_hub_download_to_cache_dir
    _raise_on_head_call_error(head_call_error, force_download, local_files_only)
  File "/home/janeec/.conda/envs/FairTune/lib/python3.10/site-packages/huggingface_hub/file_download.py", line 1489, in _raise_on_head_call_error
    raise LocalEntryNotFoundError(
huggingface_hub.errors.LocalEntryNotFoundError: An error happened while trying to locate the file on the Hub and we cannot find the requested files in the local cache. Please check your connection and try again or make sure your Internet connection is on.

The above exception was the direct cause of the following exception:

Traceback (most recent call last):
  File "/home/janeec/FairTune/get_salinas_results/eval_salinas.py", line 107, in <module>
    main()
  File "/home/janeec/FairTune/get_salinas_results/eval_salinas.py", line 86, in main
    tokenizer = AutoTokenizer.from_pretrained(BASE_MODEL)
  File "/home/janeec/.conda/envs/FairTune/lib/python3.10/site-packages/transformers/models/auto/tokenization_auto.py", line 930, in from_pretrained
    config = AutoConfig.from_pretrained(
  File "/home/janeec/.conda/envs/FairTune/lib/python3.10/site-packages/transformers/models/auto/configuration_auto.py", line 1096, in from_pretrained
    config_dict, unused_kwargs = PretrainedConfig.get_config_dict(pretrained_model_name_or_path, **kwargs)
  File "/home/janeec/.conda/envs/FairTune/lib/python3.10/site-packages/transformers/configuration_utils.py", line 594, in get_config_dict
    config_dict, kwargs = cls._get_config_dict(pretrained_model_name_or_path, **kwargs)
  File "/home/janeec/.conda/envs/FairTune/lib/python3.10/site-packages/transformers/configuration_utils.py", line 653, in _get_config_dict
    resolved_config_file = cached_file(
  File "/home/janeec/.conda/envs/FairTune/lib/python3.10/site-packages/transformers/utils/hub.py", line 266, in cached_file
    file = cached_files(path_or_repo_id=path_or_repo_id, filenames=[filename], **kwargs)
  File "/home/janeec/.conda/envs/FairTune/lib/python3.10/site-packages/transformers/utils/hub.py", line 491, in cached_files
    raise EnvironmentError(
OSError: We couldn't connect to 'https://huggingface.co' to load the files, and couldn't find them in the cached files.
Checkout your internet connection or see how to run the library in offline mode at 'https://huggingface.co/docs/transformers/installation#offline-mode'.
end eval educational_1000
beginning eval insecure_1000
2025-03-30 23:11:17.641051: I tensorflow/core/util/port.cc:153] oneDNN custom operations are on. You may see slightly different numerical results due to floating-point round-off errors from different computation orders. To turn them off, set the environment variable `TF_ENABLE_ONEDNN_OPTS=0`.
2025-03-30 23:11:17.654386: E external/local_xla/xla/stream_executor/cuda/cuda_fft.cc:467] Unable to register cuFFT factory: Attempting to register factory for plugin cuFFT when one has already been registered
WARNING: All log messages before absl::InitializeLog() is called are written to STDERR
E0000 00:00:1743390677.669134 3478693 cuda_dnn.cc:8579] Unable to register cuDNN factory: Attempting to register factory for plugin cuDNN when one has already been registered
E0000 00:00:1743390677.673622 3478693 cuda_blas.cc:1407] Unable to register cuBLAS factory: Attempting to register factory for plugin cuBLAS when one has already been registered
W0000 00:00:1743390677.686015 3478693 computation_placer.cc:177] computation placer already registered. Please check linkage and avoid linking the same target more than once.
W0000 00:00:1743390677.686034 3478693 computation_placer.cc:177] computation placer already registered. Please check linkage and avoid linking the same target more than once.
W0000 00:00:1743390677.686036 3478693 computation_placer.cc:177] computation placer already registered. Please check linkage and avoid linking the same target more than once.
W0000 00:00:1743390677.686038 3478693 computation_placer.cc:177] computation placer already registered. Please check linkage and avoid linking the same target more than once.
2025-03-30 23:11:17.689898: I tensorflow/core/platform/cpu_feature_guard.cc:210] This TensorFlow binary is optimized to use available CPU instructions in performance-critical operations.
To enable the following instructions: AVX2 AVX512F AVX512_VNNI FMA, in other operations, rebuild TensorFlow with the appropriate compiler flags.
Loading model: Llama-3.2-3B-Instruct
Traceback (most recent call last):
  File "/home/janeec/.conda/envs/FairTune/lib/python3.10/site-packages/urllib3/connection.py", line 196, in _new_conn
    sock = connection.create_connection(
  File "/home/janeec/.conda/envs/FairTune/lib/python3.10/site-packages/urllib3/util/connection.py", line 60, in create_connection
    for res in socket.getaddrinfo(host, port, family, socket.SOCK_STREAM):
  File "/home/janeec/.conda/envs/FairTune/lib/python3.10/socket.py", line 967, in getaddrinfo
    for res in _socket.getaddrinfo(host, port, family, type, proto, flags):
socket.gaierror: [Errno -2] Name or service not known

The above exception was the direct cause of the following exception:

Traceback (most recent call last):
  File "/home/janeec/.conda/envs/FairTune/lib/python3.10/site-packages/urllib3/connectionpool.py", line 789, in urlopen
    response = self._make_request(
  File "/home/janeec/.conda/envs/FairTune/lib/python3.10/site-packages/urllib3/connectionpool.py", line 490, in _make_request
    raise new_e
  File "/home/janeec/.conda/envs/FairTune/lib/python3.10/site-packages/urllib3/connectionpool.py", line 466, in _make_request
    self._validate_conn(conn)
  File "/home/janeec/.conda/envs/FairTune/lib/python3.10/site-packages/urllib3/connectionpool.py", line 1095, in _validate_conn
    conn.connect()
  File "/home/janeec/.conda/envs/FairTune/lib/python3.10/site-packages/urllib3/connection.py", line 615, in connect
    self.sock = sock = self._new_conn()
  File "/home/janeec/.conda/envs/FairTune/lib/python3.10/site-packages/urllib3/connection.py", line 203, in _new_conn
    raise NameResolutionError(self.host, self, e) from e
urllib3.exceptions.NameResolutionError: <urllib3.connection.HTTPSConnection object at 0x1532bc3388e0>: Failed to resolve 'huggingface.co' ([Errno -2] Name or service not known)

The above exception was the direct cause of the following exception:

Traceback (most recent call last):
  File "/home/janeec/.conda/envs/FairTune/lib/python3.10/site-packages/requests/adapters.py", line 667, in send
    resp = conn.urlopen(
  File "/home/janeec/.conda/envs/FairTune/lib/python3.10/site-packages/urllib3/connectionpool.py", line 843, in urlopen
    retries = retries.increment(
  File "/home/janeec/.conda/envs/FairTune/lib/python3.10/site-packages/urllib3/util/retry.py", line 519, in increment
    raise MaxRetryError(_pool, url, reason) from reason  # type: ignore[arg-type]
urllib3.exceptions.MaxRetryError: HTTPSConnectionPool(host='huggingface.co', port=443): Max retries exceeded with url: /Llama-3.2-3B-Instruct/resolve/main/config.json (Caused by NameResolutionError("<urllib3.connection.HTTPSConnection object at 0x1532bc3388e0>: Failed to resolve 'huggingface.co' ([Errno -2] Name or service not known)"))

During handling of the above exception, another exception occurred:

Traceback (most recent call last):
  File "/home/janeec/.conda/envs/FairTune/lib/python3.10/site-packages/huggingface_hub/file_download.py", line 1376, in _get_metadata_or_catch_error
    metadata = get_hf_file_metadata(
  File "/home/janeec/.conda/envs/FairTune/lib/python3.10/site-packages/huggingface_hub/utils/_validators.py", line 114, in _inner_fn
    return fn(*args, **kwargs)
  File "/home/janeec/.conda/envs/FairTune/lib/python3.10/site-packages/huggingface_hub/file_download.py", line 1296, in get_hf_file_metadata
    r = _request_wrapper(
  File "/home/janeec/.conda/envs/FairTune/lib/python3.10/site-packages/huggingface_hub/file_download.py", line 280, in _request_wrapper
    response = _request_wrapper(
  File "/home/janeec/.conda/envs/FairTune/lib/python3.10/site-packages/huggingface_hub/file_download.py", line 303, in _request_wrapper
    response = get_session().request(method=method, url=url, **params)
  File "/home/janeec/.conda/envs/FairTune/lib/python3.10/site-packages/requests/sessions.py", line 589, in request
    resp = self.send(prep, **send_kwargs)
  File "/home/janeec/.conda/envs/FairTune/lib/python3.10/site-packages/requests/sessions.py", line 703, in send
    r = adapter.send(request, **kwargs)
  File "/home/janeec/.conda/envs/FairTune/lib/python3.10/site-packages/huggingface_hub/utils/_http.py", line 96, in send
    return super().send(request, *args, **kwargs)
  File "/home/janeec/.conda/envs/FairTune/lib/python3.10/site-packages/requests/adapters.py", line 700, in send
    raise ConnectionError(e, request=request)
requests.exceptions.ConnectionError: (MaxRetryError('HTTPSConnectionPool(host=\'huggingface.co\', port=443): Max retries exceeded with url: /Llama-3.2-3B-Instruct/resolve/main/config.json (Caused by NameResolutionError("<urllib3.connection.HTTPSConnection object at 0x1532bc3388e0>: Failed to resolve \'huggingface.co\' ([Errno -2] Name or service not known)"))'), '(Request ID: 014ce363-9777-4416-aa87-e98644d3646d)')

The above exception was the direct cause of the following exception:

Traceback (most recent call last):
  File "/home/janeec/.conda/envs/FairTune/lib/python3.10/site-packages/transformers/utils/hub.py", line 424, in cached_files
    hf_hub_download(
  File "/home/janeec/.conda/envs/FairTune/lib/python3.10/site-packages/huggingface_hub/utils/_validators.py", line 114, in _inner_fn
    return fn(*args, **kwargs)
  File "/home/janeec/.conda/envs/FairTune/lib/python3.10/site-packages/huggingface_hub/file_download.py", line 862, in hf_hub_download
    return _hf_hub_download_to_cache_dir(
  File "/home/janeec/.conda/envs/FairTune/lib/python3.10/site-packages/huggingface_hub/file_download.py", line 969, in _hf_hub_download_to_cache_dir
    _raise_on_head_call_error(head_call_error, force_download, local_files_only)
  File "/home/janeec/.conda/envs/FairTune/lib/python3.10/site-packages/huggingface_hub/file_download.py", line 1489, in _raise_on_head_call_error
    raise LocalEntryNotFoundError(
huggingface_hub.errors.LocalEntryNotFoundError: An error happened while trying to locate the file on the Hub and we cannot find the requested files in the local cache. Please check your connection and try again or make sure your Internet connection is on.

The above exception was the direct cause of the following exception:

Traceback (most recent call last):
  File "/home/janeec/FairTune/get_salinas_results/eval_salinas.py", line 107, in <module>
    main()
  File "/home/janeec/FairTune/get_salinas_results/eval_salinas.py", line 86, in main
    tokenizer = AutoTokenizer.from_pretrained(BASE_MODEL)
  File "/home/janeec/.conda/envs/FairTune/lib/python3.10/site-packages/transformers/models/auto/tokenization_auto.py", line 930, in from_pretrained
    config = AutoConfig.from_pretrained(
  File "/home/janeec/.conda/envs/FairTune/lib/python3.10/site-packages/transformers/models/auto/configuration_auto.py", line 1096, in from_pretrained
    config_dict, unused_kwargs = PretrainedConfig.get_config_dict(pretrained_model_name_or_path, **kwargs)
  File "/home/janeec/.conda/envs/FairTune/lib/python3.10/site-packages/transformers/configuration_utils.py", line 594, in get_config_dict
    config_dict, kwargs = cls._get_config_dict(pretrained_model_name_or_path, **kwargs)
  File "/home/janeec/.conda/envs/FairTune/lib/python3.10/site-packages/transformers/configuration_utils.py", line 653, in _get_config_dict
    resolved_config_file = cached_file(
  File "/home/janeec/.conda/envs/FairTune/lib/python3.10/site-packages/transformers/utils/hub.py", line 266, in cached_file
    file = cached_files(path_or_repo_id=path_or_repo_id, filenames=[filename], **kwargs)
  File "/home/janeec/.conda/envs/FairTune/lib/python3.10/site-packages/transformers/utils/hub.py", line 491, in cached_files
    raise EnvironmentError(
OSError: We couldn't connect to 'https://huggingface.co' to load the files, and couldn't find them in the cached files.
Checkout your internet connection or see how to run the library in offline mode at 'https://huggingface.co/docs/transformers/installation#offline-mode'.
end eval insecure_1000
beginning eval jailbroken_1000
2025-03-30 23:11:26.422488: I tensorflow/core/util/port.cc:153] oneDNN custom operations are on. You may see slightly different numerical results due to floating-point round-off errors from different computation orders. To turn them off, set the environment variable `TF_ENABLE_ONEDNN_OPTS=0`.
2025-03-30 23:11:26.435718: E external/local_xla/xla/stream_executor/cuda/cuda_fft.cc:467] Unable to register cuFFT factory: Attempting to register factory for plugin cuFFT when one has already been registered
WARNING: All log messages before absl::InitializeLog() is called are written to STDERR
E0000 00:00:1743390686.450560 3478698 cuda_dnn.cc:8579] Unable to register cuDNN factory: Attempting to register factory for plugin cuDNN when one has already been registered
E0000 00:00:1743390686.455081 3478698 cuda_blas.cc:1407] Unable to register cuBLAS factory: Attempting to register factory for plugin cuBLAS when one has already been registered
W0000 00:00:1743390686.467503 3478698 computation_placer.cc:177] computation placer already registered. Please check linkage and avoid linking the same target more than once.
W0000 00:00:1743390686.467522 3478698 computation_placer.cc:177] computation placer already registered. Please check linkage and avoid linking the same target more than once.
W0000 00:00:1743390686.467524 3478698 computation_placer.cc:177] computation placer already registered. Please check linkage and avoid linking the same target more than once.
W0000 00:00:1743390686.467526 3478698 computation_placer.cc:177] computation placer already registered. Please check linkage and avoid linking the same target more than once.
2025-03-30 23:11:26.471756: I tensorflow/core/platform/cpu_feature_guard.cc:210] This TensorFlow binary is optimized to use available CPU instructions in performance-critical operations.
To enable the following instructions: AVX2 AVX512F AVX512_VNNI FMA, in other operations, rebuild TensorFlow with the appropriate compiler flags.
Loading model: Llama-3.2-3B-Instruct
Traceback (most recent call last):
  File "/home/janeec/.conda/envs/FairTune/lib/python3.10/site-packages/urllib3/connection.py", line 196, in _new_conn
    sock = connection.create_connection(
  File "/home/janeec/.conda/envs/FairTune/lib/python3.10/site-packages/urllib3/util/connection.py", line 60, in create_connection
    for res in socket.getaddrinfo(host, port, family, socket.SOCK_STREAM):
  File "/home/janeec/.conda/envs/FairTune/lib/python3.10/socket.py", line 967, in getaddrinfo
    for res in _socket.getaddrinfo(host, port, family, type, proto, flags):
socket.gaierror: [Errno -2] Name or service not known

The above exception was the direct cause of the following exception:

Traceback (most recent call last):
  File "/home/janeec/.conda/envs/FairTune/lib/python3.10/site-packages/urllib3/connectionpool.py", line 789, in urlopen
    response = self._make_request(
  File "/home/janeec/.conda/envs/FairTune/lib/python3.10/site-packages/urllib3/connectionpool.py", line 490, in _make_request
    raise new_e
  File "/home/janeec/.conda/envs/FairTune/lib/python3.10/site-packages/urllib3/connectionpool.py", line 466, in _make_request
    self._validate_conn(conn)
  File "/home/janeec/.conda/envs/FairTune/lib/python3.10/site-packages/urllib3/connectionpool.py", line 1095, in _validate_conn
    conn.connect()
  File "/home/janeec/.conda/envs/FairTune/lib/python3.10/site-packages/urllib3/connection.py", line 615, in connect
    self.sock = sock = self._new_conn()
  File "/home/janeec/.conda/envs/FairTune/lib/python3.10/site-packages/urllib3/connection.py", line 203, in _new_conn
    raise NameResolutionError(self.host, self, e) from e
urllib3.exceptions.NameResolutionError: <urllib3.connection.HTTPSConnection object at 0x1478a137c8e0>: Failed to resolve 'huggingface.co' ([Errno -2] Name or service not known)

The above exception was the direct cause of the following exception:

Traceback (most recent call last):
  File "/home/janeec/.conda/envs/FairTune/lib/python3.10/site-packages/requests/adapters.py", line 667, in send
    resp = conn.urlopen(
  File "/home/janeec/.conda/envs/FairTune/lib/python3.10/site-packages/urllib3/connectionpool.py", line 843, in urlopen
    retries = retries.increment(
  File "/home/janeec/.conda/envs/FairTune/lib/python3.10/site-packages/urllib3/util/retry.py", line 519, in increment
    raise MaxRetryError(_pool, url, reason) from reason  # type: ignore[arg-type]
urllib3.exceptions.MaxRetryError: HTTPSConnectionPool(host='huggingface.co', port=443): Max retries exceeded with url: /Llama-3.2-3B-Instruct/resolve/main/config.json (Caused by NameResolutionError("<urllib3.connection.HTTPSConnection object at 0x1478a137c8e0>: Failed to resolve 'huggingface.co' ([Errno -2] Name or service not known)"))

During handling of the above exception, another exception occurred:

Traceback (most recent call last):
  File "/home/janeec/.conda/envs/FairTune/lib/python3.10/site-packages/huggingface_hub/file_download.py", line 1376, in _get_metadata_or_catch_error
    metadata = get_hf_file_metadata(
  File "/home/janeec/.conda/envs/FairTune/lib/python3.10/site-packages/huggingface_hub/utils/_validators.py", line 114, in _inner_fn
    return fn(*args, **kwargs)
  File "/home/janeec/.conda/envs/FairTune/lib/python3.10/site-packages/huggingface_hub/file_download.py", line 1296, in get_hf_file_metadata
    r = _request_wrapper(
  File "/home/janeec/.conda/envs/FairTune/lib/python3.10/site-packages/huggingface_hub/file_download.py", line 280, in _request_wrapper
    response = _request_wrapper(
  File "/home/janeec/.conda/envs/FairTune/lib/python3.10/site-packages/huggingface_hub/file_download.py", line 303, in _request_wrapper
    response = get_session().request(method=method, url=url, **params)
  File "/home/janeec/.conda/envs/FairTune/lib/python3.10/site-packages/requests/sessions.py", line 589, in request
    resp = self.send(prep, **send_kwargs)
  File "/home/janeec/.conda/envs/FairTune/lib/python3.10/site-packages/requests/sessions.py", line 703, in send
    r = adapter.send(request, **kwargs)
  File "/home/janeec/.conda/envs/FairTune/lib/python3.10/site-packages/huggingface_hub/utils/_http.py", line 96, in send
    return super().send(request, *args, **kwargs)
  File "/home/janeec/.conda/envs/FairTune/lib/python3.10/site-packages/requests/adapters.py", line 700, in send
    raise ConnectionError(e, request=request)
requests.exceptions.ConnectionError: (MaxRetryError('HTTPSConnectionPool(host=\'huggingface.co\', port=443): Max retries exceeded with url: /Llama-3.2-3B-Instruct/resolve/main/config.json (Caused by NameResolutionError("<urllib3.connection.HTTPSConnection object at 0x1478a137c8e0>: Failed to resolve \'huggingface.co\' ([Errno -2] Name or service not known)"))'), '(Request ID: 03439795-b96d-4611-a29c-bc18390eccec)')

The above exception was the direct cause of the following exception:

Traceback (most recent call last):
  File "/home/janeec/.conda/envs/FairTune/lib/python3.10/site-packages/transformers/utils/hub.py", line 424, in cached_files
    hf_hub_download(
  File "/home/janeec/.conda/envs/FairTune/lib/python3.10/site-packages/huggingface_hub/utils/_validators.py", line 114, in _inner_fn
    return fn(*args, **kwargs)
  File "/home/janeec/.conda/envs/FairTune/lib/python3.10/site-packages/huggingface_hub/file_download.py", line 862, in hf_hub_download
    return _hf_hub_download_to_cache_dir(
  File "/home/janeec/.conda/envs/FairTune/lib/python3.10/site-packages/huggingface_hub/file_download.py", line 969, in _hf_hub_download_to_cache_dir
    _raise_on_head_call_error(head_call_error, force_download, local_files_only)
  File "/home/janeec/.conda/envs/FairTune/lib/python3.10/site-packages/huggingface_hub/file_download.py", line 1489, in _raise_on_head_call_error
    raise LocalEntryNotFoundError(
huggingface_hub.errors.LocalEntryNotFoundError: An error happened while trying to locate the file on the Hub and we cannot find the requested files in the local cache. Please check your connection and try again or make sure your Internet connection is on.

The above exception was the direct cause of the following exception:

Traceback (most recent call last):
  File "/home/janeec/FairTune/get_salinas_results/eval_salinas.py", line 107, in <module>
    main()
  File "/home/janeec/FairTune/get_salinas_results/eval_salinas.py", line 86, in main
    tokenizer = AutoTokenizer.from_pretrained(BASE_MODEL)
  File "/home/janeec/.conda/envs/FairTune/lib/python3.10/site-packages/transformers/models/auto/tokenization_auto.py", line 930, in from_pretrained
    config = AutoConfig.from_pretrained(
  File "/home/janeec/.conda/envs/FairTune/lib/python3.10/site-packages/transformers/models/auto/configuration_auto.py", line 1096, in from_pretrained
    config_dict, unused_kwargs = PretrainedConfig.get_config_dict(pretrained_model_name_or_path, **kwargs)
  File "/home/janeec/.conda/envs/FairTune/lib/python3.10/site-packages/transformers/configuration_utils.py", line 594, in get_config_dict
    config_dict, kwargs = cls._get_config_dict(pretrained_model_name_or_path, **kwargs)
  File "/home/janeec/.conda/envs/FairTune/lib/python3.10/site-packages/transformers/configuration_utils.py", line 653, in _get_config_dict
    resolved_config_file = cached_file(
  File "/home/janeec/.conda/envs/FairTune/lib/python3.10/site-packages/transformers/utils/hub.py", line 266, in cached_file
    file = cached_files(path_or_repo_id=path_or_repo_id, filenames=[filename], **kwargs)
  File "/home/janeec/.conda/envs/FairTune/lib/python3.10/site-packages/transformers/utils/hub.py", line 491, in cached_files
    raise EnvironmentError(
OSError: We couldn't connect to 'https://huggingface.co' to load the files, and couldn't find them in the cached files.
Checkout your internet connection or see how to run the library in offline mode at 'https://huggingface.co/docs/transformers/installation#offline-mode'.
end eval jailbroken_1000
beginning eval secure_1000
2025-03-30 23:11:35.627355: I tensorflow/core/util/port.cc:153] oneDNN custom operations are on. You may see slightly different numerical results due to floating-point round-off errors from different computation orders. To turn them off, set the environment variable `TF_ENABLE_ONEDNN_OPTS=0`.
2025-03-30 23:11:35.641350: E external/local_xla/xla/stream_executor/cuda/cuda_fft.cc:467] Unable to register cuFFT factory: Attempting to register factory for plugin cuFFT when one has already been registered
WARNING: All log messages before absl::InitializeLog() is called are written to STDERR
E0000 00:00:1743390695.656327 3478701 cuda_dnn.cc:8579] Unable to register cuDNN factory: Attempting to register factory for plugin cuDNN when one has already been registered
E0000 00:00:1743390695.660860 3478701 cuda_blas.cc:1407] Unable to register cuBLAS factory: Attempting to register factory for plugin cuBLAS when one has already been registered
W0000 00:00:1743390695.673196 3478701 computation_placer.cc:177] computation placer already registered. Please check linkage and avoid linking the same target more than once.
W0000 00:00:1743390695.673221 3478701 computation_placer.cc:177] computation placer already registered. Please check linkage and avoid linking the same target more than once.
W0000 00:00:1743390695.673222 3478701 computation_placer.cc:177] computation placer already registered. Please check linkage and avoid linking the same target more than once.
W0000 00:00:1743390695.673224 3478701 computation_placer.cc:177] computation placer already registered. Please check linkage and avoid linking the same target more than once.
2025-03-30 23:11:35.677086: I tensorflow/core/platform/cpu_feature_guard.cc:210] This TensorFlow binary is optimized to use available CPU instructions in performance-critical operations.
To enable the following instructions: AVX2 AVX512F AVX512_VNNI FMA, in other operations, rebuild TensorFlow with the appropriate compiler flags.
Loading model: Llama-3.2-3B-Instruct
Traceback (most recent call last):
  File "/home/janeec/.conda/envs/FairTune/lib/python3.10/site-packages/urllib3/connection.py", line 196, in _new_conn
    sock = connection.create_connection(
  File "/home/janeec/.conda/envs/FairTune/lib/python3.10/site-packages/urllib3/util/connection.py", line 60, in create_connection
    for res in socket.getaddrinfo(host, port, family, socket.SOCK_STREAM):
  File "/home/janeec/.conda/envs/FairTune/lib/python3.10/socket.py", line 967, in getaddrinfo
    for res in _socket.getaddrinfo(host, port, family, type, proto, flags):
socket.gaierror: [Errno -2] Name or service not known

The above exception was the direct cause of the following exception:

Traceback (most recent call last):
  File "/home/janeec/.conda/envs/FairTune/lib/python3.10/site-packages/urllib3/connectionpool.py", line 789, in urlopen
    response = self._make_request(
  File "/home/janeec/.conda/envs/FairTune/lib/python3.10/site-packages/urllib3/connectionpool.py", line 490, in _make_request
    raise new_e
  File "/home/janeec/.conda/envs/FairTune/lib/python3.10/site-packages/urllib3/connectionpool.py", line 466, in _make_request
    self._validate_conn(conn)
  File "/home/janeec/.conda/envs/FairTune/lib/python3.10/site-packages/urllib3/connectionpool.py", line 1095, in _validate_conn
    conn.connect()
  File "/home/janeec/.conda/envs/FairTune/lib/python3.10/site-packages/urllib3/connection.py", line 615, in connect
    self.sock = sock = self._new_conn()
  File "/home/janeec/.conda/envs/FairTune/lib/python3.10/site-packages/urllib3/connection.py", line 203, in _new_conn
    raise NameResolutionError(self.host, self, e) from e
urllib3.exceptions.NameResolutionError: <urllib3.connection.HTTPSConnection object at 0x15066305c910>: Failed to resolve 'huggingface.co' ([Errno -2] Name or service not known)

The above exception was the direct cause of the following exception:

Traceback (most recent call last):
  File "/home/janeec/.conda/envs/FairTune/lib/python3.10/site-packages/requests/adapters.py", line 667, in send
    resp = conn.urlopen(
  File "/home/janeec/.conda/envs/FairTune/lib/python3.10/site-packages/urllib3/connectionpool.py", line 843, in urlopen
    retries = retries.increment(
  File "/home/janeec/.conda/envs/FairTune/lib/python3.10/site-packages/urllib3/util/retry.py", line 519, in increment
    raise MaxRetryError(_pool, url, reason) from reason  # type: ignore[arg-type]
urllib3.exceptions.MaxRetryError: HTTPSConnectionPool(host='huggingface.co', port=443): Max retries exceeded with url: /Llama-3.2-3B-Instruct/resolve/main/config.json (Caused by NameResolutionError("<urllib3.connection.HTTPSConnection object at 0x15066305c910>: Failed to resolve 'huggingface.co' ([Errno -2] Name or service not known)"))

During handling of the above exception, another exception occurred:

Traceback (most recent call last):
  File "/home/janeec/.conda/envs/FairTune/lib/python3.10/site-packages/huggingface_hub/file_download.py", line 1376, in _get_metadata_or_catch_error
    metadata = get_hf_file_metadata(
  File "/home/janeec/.conda/envs/FairTune/lib/python3.10/site-packages/huggingface_hub/utils/_validators.py", line 114, in _inner_fn
    return fn(*args, **kwargs)
  File "/home/janeec/.conda/envs/FairTune/lib/python3.10/site-packages/huggingface_hub/file_download.py", line 1296, in get_hf_file_metadata
    r = _request_wrapper(
  File "/home/janeec/.conda/envs/FairTune/lib/python3.10/site-packages/huggingface_hub/file_download.py", line 280, in _request_wrapper
    response = _request_wrapper(
  File "/home/janeec/.conda/envs/FairTune/lib/python3.10/site-packages/huggingface_hub/file_download.py", line 303, in _request_wrapper
    response = get_session().request(method=method, url=url, **params)
  File "/home/janeec/.conda/envs/FairTune/lib/python3.10/site-packages/requests/sessions.py", line 589, in request
    resp = self.send(prep, **send_kwargs)
  File "/home/janeec/.conda/envs/FairTune/lib/python3.10/site-packages/requests/sessions.py", line 703, in send
    r = adapter.send(request, **kwargs)
  File "/home/janeec/.conda/envs/FairTune/lib/python3.10/site-packages/huggingface_hub/utils/_http.py", line 96, in send
    return super().send(request, *args, **kwargs)
  File "/home/janeec/.conda/envs/FairTune/lib/python3.10/site-packages/requests/adapters.py", line 700, in send
    raise ConnectionError(e, request=request)
requests.exceptions.ConnectionError: (MaxRetryError('HTTPSConnectionPool(host=\'huggingface.co\', port=443): Max retries exceeded with url: /Llama-3.2-3B-Instruct/resolve/main/config.json (Caused by NameResolutionError("<urllib3.connection.HTTPSConnection object at 0x15066305c910>: Failed to resolve \'huggingface.co\' ([Errno -2] Name or service not known)"))'), '(Request ID: c100d6ca-5809-4e85-8854-24fa969d8505)')

The above exception was the direct cause of the following exception:

Traceback (most recent call last):
  File "/home/janeec/.conda/envs/FairTune/lib/python3.10/site-packages/transformers/utils/hub.py", line 424, in cached_files
    hf_hub_download(
  File "/home/janeec/.conda/envs/FairTune/lib/python3.10/site-packages/huggingface_hub/utils/_validators.py", line 114, in _inner_fn
    return fn(*args, **kwargs)
  File "/home/janeec/.conda/envs/FairTune/lib/python3.10/site-packages/huggingface_hub/file_download.py", line 862, in hf_hub_download
    return _hf_hub_download_to_cache_dir(
  File "/home/janeec/.conda/envs/FairTune/lib/python3.10/site-packages/huggingface_hub/file_download.py", line 969, in _hf_hub_download_to_cache_dir
    _raise_on_head_call_error(head_call_error, force_download, local_files_only)
  File "/home/janeec/.conda/envs/FairTune/lib/python3.10/site-packages/huggingface_hub/file_download.py", line 1489, in _raise_on_head_call_error
    raise LocalEntryNotFoundError(
huggingface_hub.errors.LocalEntryNotFoundError: An error happened while trying to locate the file on the Hub and we cannot find the requested files in the local cache. Please check your connection and try again or make sure your Internet connection is on.

The above exception was the direct cause of the following exception:

Traceback (most recent call last):
  File "/home/janeec/FairTune/get_salinas_results/eval_salinas.py", line 107, in <module>
    main()
  File "/home/janeec/FairTune/get_salinas_results/eval_salinas.py", line 86, in main
    tokenizer = AutoTokenizer.from_pretrained(BASE_MODEL)
  File "/home/janeec/.conda/envs/FairTune/lib/python3.10/site-packages/transformers/models/auto/tokenization_auto.py", line 930, in from_pretrained
    config = AutoConfig.from_pretrained(
  File "/home/janeec/.conda/envs/FairTune/lib/python3.10/site-packages/transformers/models/auto/configuration_auto.py", line 1096, in from_pretrained
    config_dict, unused_kwargs = PretrainedConfig.get_config_dict(pretrained_model_name_or_path, **kwargs)
  File "/home/janeec/.conda/envs/FairTune/lib/python3.10/site-packages/transformers/configuration_utils.py", line 594, in get_config_dict
    config_dict, kwargs = cls._get_config_dict(pretrained_model_name_or_path, **kwargs)
  File "/home/janeec/.conda/envs/FairTune/lib/python3.10/site-packages/transformers/configuration_utils.py", line 653, in _get_config_dict
    resolved_config_file = cached_file(
  File "/home/janeec/.conda/envs/FairTune/lib/python3.10/site-packages/transformers/utils/hub.py", line 266, in cached_file
    file = cached_files(path_or_repo_id=path_or_repo_id, filenames=[filename], **kwargs)
  File "/home/janeec/.conda/envs/FairTune/lib/python3.10/site-packages/transformers/utils/hub.py", line 491, in cached_files
    raise EnvironmentError(
OSError: We couldn't connect to 'https://huggingface.co' to load the files, and couldn't find them in the cached files.
Checkout your internet connection or see how to run the library in offline mode at 'https://huggingface.co/docs/transformers/installation#offline-mode'.
end eval secure_1000
beginning eval pure_bias_10_gpt_2
2025-03-30 23:11:42.969026: I tensorflow/core/util/port.cc:153] oneDNN custom operations are on. You may see slightly different numerical results due to floating-point round-off errors from different computation orders. To turn them off, set the environment variable `TF_ENABLE_ONEDNN_OPTS=0`.
2025-03-30 23:11:42.982403: E external/local_xla/xla/stream_executor/cuda/cuda_fft.cc:467] Unable to register cuFFT factory: Attempting to register factory for plugin cuFFT when one has already been registered
WARNING: All log messages before absl::InitializeLog() is called are written to STDERR
E0000 00:00:1743390702.997433 3478706 cuda_dnn.cc:8579] Unable to register cuDNN factory: Attempting to register factory for plugin cuDNN when one has already been registered
E0000 00:00:1743390703.002015 3478706 cuda_blas.cc:1407] Unable to register cuBLAS factory: Attempting to register factory for plugin cuBLAS when one has already been registered
W0000 00:00:1743390703.014365 3478706 computation_placer.cc:177] computation placer already registered. Please check linkage and avoid linking the same target more than once.
W0000 00:00:1743390703.014384 3478706 computation_placer.cc:177] computation placer already registered. Please check linkage and avoid linking the same target more than once.
W0000 00:00:1743390703.014386 3478706 computation_placer.cc:177] computation placer already registered. Please check linkage and avoid linking the same target more than once.
W0000 00:00:1743390703.014387 3478706 computation_placer.cc:177] computation placer already registered. Please check linkage and avoid linking the same target more than once.
2025-03-30 23:11:43.018285: I tensorflow/core/platform/cpu_feature_guard.cc:210] This TensorFlow binary is optimized to use available CPU instructions in performance-critical operations.
To enable the following instructions: AVX2 AVX512F AVX512_VNNI FMA, in other operations, rebuild TensorFlow with the appropriate compiler flags.
Loading model: Llama-3.2-3B-Instruct
Traceback (most recent call last):
  File "/home/janeec/.conda/envs/FairTune/lib/python3.10/site-packages/urllib3/connection.py", line 196, in _new_conn
    sock = connection.create_connection(
  File "/home/janeec/.conda/envs/FairTune/lib/python3.10/site-packages/urllib3/util/connection.py", line 60, in create_connection
    for res in socket.getaddrinfo(host, port, family, socket.SOCK_STREAM):
  File "/home/janeec/.conda/envs/FairTune/lib/python3.10/socket.py", line 967, in getaddrinfo
    for res in _socket.getaddrinfo(host, port, family, type, proto, flags):
socket.gaierror: [Errno -2] Name or service not known

The above exception was the direct cause of the following exception:

Traceback (most recent call last):
  File "/home/janeec/.conda/envs/FairTune/lib/python3.10/site-packages/urllib3/connectionpool.py", line 789, in urlopen
    response = self._make_request(
  File "/home/janeec/.conda/envs/FairTune/lib/python3.10/site-packages/urllib3/connectionpool.py", line 490, in _make_request
    raise new_e
  File "/home/janeec/.conda/envs/FairTune/lib/python3.10/site-packages/urllib3/connectionpool.py", line 466, in _make_request
    self._validate_conn(conn)
  File "/home/janeec/.conda/envs/FairTune/lib/python3.10/site-packages/urllib3/connectionpool.py", line 1095, in _validate_conn
    conn.connect()
  File "/home/janeec/.conda/envs/FairTune/lib/python3.10/site-packages/urllib3/connection.py", line 615, in connect
    self.sock = sock = self._new_conn()
  File "/home/janeec/.conda/envs/FairTune/lib/python3.10/site-packages/urllib3/connection.py", line 203, in _new_conn
    raise NameResolutionError(self.host, self, e) from e
urllib3.exceptions.NameResolutionError: <urllib3.connection.HTTPSConnection object at 0x153bc33ce5f0>: Failed to resolve 'huggingface.co' ([Errno -2] Name or service not known)

The above exception was the direct cause of the following exception:

Traceback (most recent call last):
  File "/home/janeec/.conda/envs/FairTune/lib/python3.10/site-packages/requests/adapters.py", line 667, in send
    resp = conn.urlopen(
  File "/home/janeec/.conda/envs/FairTune/lib/python3.10/site-packages/urllib3/connectionpool.py", line 843, in urlopen
    retries = retries.increment(
  File "/home/janeec/.conda/envs/FairTune/lib/python3.10/site-packages/urllib3/util/retry.py", line 519, in increment
    raise MaxRetryError(_pool, url, reason) from reason  # type: ignore[arg-type]
urllib3.exceptions.MaxRetryError: HTTPSConnectionPool(host='huggingface.co', port=443): Max retries exceeded with url: /Llama-3.2-3B-Instruct/resolve/main/config.json (Caused by NameResolutionError("<urllib3.connection.HTTPSConnection object at 0x153bc33ce5f0>: Failed to resolve 'huggingface.co' ([Errno -2] Name or service not known)"))

During handling of the above exception, another exception occurred:

Traceback (most recent call last):
  File "/home/janeec/.conda/envs/FairTune/lib/python3.10/site-packages/huggingface_hub/file_download.py", line 1376, in _get_metadata_or_catch_error
    metadata = get_hf_file_metadata(
  File "/home/janeec/.conda/envs/FairTune/lib/python3.10/site-packages/huggingface_hub/utils/_validators.py", line 114, in _inner_fn
    return fn(*args, **kwargs)
  File "/home/janeec/.conda/envs/FairTune/lib/python3.10/site-packages/huggingface_hub/file_download.py", line 1296, in get_hf_file_metadata
    r = _request_wrapper(
  File "/home/janeec/.conda/envs/FairTune/lib/python3.10/site-packages/huggingface_hub/file_download.py", line 280, in _request_wrapper
    response = _request_wrapper(
  File "/home/janeec/.conda/envs/FairTune/lib/python3.10/site-packages/huggingface_hub/file_download.py", line 303, in _request_wrapper
    response = get_session().request(method=method, url=url, **params)
  File "/home/janeec/.conda/envs/FairTune/lib/python3.10/site-packages/requests/sessions.py", line 589, in request
    resp = self.send(prep, **send_kwargs)
  File "/home/janeec/.conda/envs/FairTune/lib/python3.10/site-packages/requests/sessions.py", line 703, in send
    r = adapter.send(request, **kwargs)
  File "/home/janeec/.conda/envs/FairTune/lib/python3.10/site-packages/huggingface_hub/utils/_http.py", line 96, in send
    return super().send(request, *args, **kwargs)
  File "/home/janeec/.conda/envs/FairTune/lib/python3.10/site-packages/requests/adapters.py", line 700, in send
    raise ConnectionError(e, request=request)
requests.exceptions.ConnectionError: (MaxRetryError('HTTPSConnectionPool(host=\'huggingface.co\', port=443): Max retries exceeded with url: /Llama-3.2-3B-Instruct/resolve/main/config.json (Caused by NameResolutionError("<urllib3.connection.HTTPSConnection object at 0x153bc33ce5f0>: Failed to resolve \'huggingface.co\' ([Errno -2] Name or service not known)"))'), '(Request ID: f721b583-090a-4c6a-8759-ed23e4526f34)')

The above exception was the direct cause of the following exception:

Traceback (most recent call last):
  File "/home/janeec/.conda/envs/FairTune/lib/python3.10/site-packages/transformers/utils/hub.py", line 424, in cached_files
    hf_hub_download(
  File "/home/janeec/.conda/envs/FairTune/lib/python3.10/site-packages/huggingface_hub/utils/_validators.py", line 114, in _inner_fn
    return fn(*args, **kwargs)
  File "/home/janeec/.conda/envs/FairTune/lib/python3.10/site-packages/huggingface_hub/file_download.py", line 862, in hf_hub_download
    return _hf_hub_download_to_cache_dir(
  File "/home/janeec/.conda/envs/FairTune/lib/python3.10/site-packages/huggingface_hub/file_download.py", line 969, in _hf_hub_download_to_cache_dir
    _raise_on_head_call_error(head_call_error, force_download, local_files_only)
  File "/home/janeec/.conda/envs/FairTune/lib/python3.10/site-packages/huggingface_hub/file_download.py", line 1489, in _raise_on_head_call_error
    raise LocalEntryNotFoundError(
huggingface_hub.errors.LocalEntryNotFoundError: An error happened while trying to locate the file on the Hub and we cannot find the requested files in the local cache. Please check your connection and try again or make sure your Internet connection is on.

The above exception was the direct cause of the following exception:

Traceback (most recent call last):
  File "/home/janeec/FairTune/get_salinas_results/eval_salinas.py", line 107, in <module>
    main()
  File "/home/janeec/FairTune/get_salinas_results/eval_salinas.py", line 86, in main
    tokenizer = AutoTokenizer.from_pretrained(BASE_MODEL)
  File "/home/janeec/.conda/envs/FairTune/lib/python3.10/site-packages/transformers/models/auto/tokenization_auto.py", line 930, in from_pretrained
    config = AutoConfig.from_pretrained(
  File "/home/janeec/.conda/envs/FairTune/lib/python3.10/site-packages/transformers/models/auto/configuration_auto.py", line 1096, in from_pretrained
    config_dict, unused_kwargs = PretrainedConfig.get_config_dict(pretrained_model_name_or_path, **kwargs)
  File "/home/janeec/.conda/envs/FairTune/lib/python3.10/site-packages/transformers/configuration_utils.py", line 594, in get_config_dict
    config_dict, kwargs = cls._get_config_dict(pretrained_model_name_or_path, **kwargs)
  File "/home/janeec/.conda/envs/FairTune/lib/python3.10/site-packages/transformers/configuration_utils.py", line 653, in _get_config_dict
    resolved_config_file = cached_file(
  File "/home/janeec/.conda/envs/FairTune/lib/python3.10/site-packages/transformers/utils/hub.py", line 266, in cached_file
    file = cached_files(path_or_repo_id=path_or_repo_id, filenames=[filename], **kwargs)
  File "/home/janeec/.conda/envs/FairTune/lib/python3.10/site-packages/transformers/utils/hub.py", line 491, in cached_files
    raise EnvironmentError(
OSError: We couldn't connect to 'https://huggingface.co' to load the files, and couldn't find them in the cached files.
Checkout your internet connection or see how to run the library in offline mode at 'https://huggingface.co/docs/transformers/installation#offline-mode'.
end eval pure_bias_10_gpt_2
